<?xml version="1.0" ?>
<!-- =================================================================================== -->
<!-- |    This document was autogenerated by xacro from /home/zaid/catkin_ws/src/mocha/urdf/mocha.urdf.xacro | -->
<!-- |    EDITING THIS FILE BY HAND IS NOT RECOMMENDED                                 | -->
<!-- =================================================================================== -->
<!-- This URDF was automatically created by SolidWorks to URDF Exporter! Originally created by Stephen Brawner (brawner@gmail.com) 
     Commit Version: 1.6.0-4-g7f85cfe  Build Version: 1.6.7995.38578
     For more information, please see http://wiki.ros.org/sw_urdf_exporter -->
<robot name="mocha">
    <link name="world" />
    <joint name="base_joint" type="fixed">
        <parent link="world" />
        <child link="base_link" />
        <origin rpy="0 0 0" xyz="0.0 0.0 0.0" />
    </joint>
    <link name="base_link">
        <inertial>
            <origin rpy="0 0 0" xyz="0.000117199417675082 -3.05975474124143E-09 0.0223035723181941" />
            <mass value="0.0979582534406825" />
            <inertia ixx="0.000130552228522341" ixy="-2.22674811046477E-11" ixz="3.99226744269731E-06" iyy="0.000140414184143385" iyz="4.13550991731117E-13" izz="0.000212143374979004" />
        </inertial>
        <visual>
            <origin rpy="0 0 0" xyz="0 0 0" />
            <geometry>
                <mesh filename="package://mocha/meshes/base_link.STL" />
            </geometry>
            <material name="">
                <color rgba="1 1 1 1" />
            </material>
        </visual>
        <collision>
            <origin rpy="0 0 0" xyz="0 0 0" />
            <geometry>
                <mesh filename="package://mocha/meshes/base_link.STL" />
            </geometry>
        </collision>
    </link>
    <link name="waist">
        <inertial>
            <origin rpy="0 0 0" xyz="0.00169136098501852 0.00660819498532267 0.0133947545307733" />
            <mass value="0.0684427129118219" />
            <inertia ixx="4.56870454663408E-05" ixy="-3.78506837372467E-07" ixz="-6.20385180122017E-06" iyy="5.87238842271773E-05" iyz="-5.19129521124936E-06" izz="5.50839190250212E-05" />
        </inertial>
        <visual>
            <origin rpy="0 0 0" xyz="0 0 0" />
            <geometry>
                <mesh filename="package://mocha/meshes/waist.STL" />
            </geometry>
            <material name="">
                <color rgba="1 1 1 1" />
            </material>
        </visual>
        <collision>
            <origin rpy="0 0 0" xyz="0 0 0" />
            <geometry>
                <mesh filename="package://mocha/meshes/waist.STL" />
            </geometry>
        </collision>
    </link>
    <joint name="waist_joint" type="revolute">
        <origin rpy="0 0 0" xyz="0 0 0.06" />
        <parent link="base_link" />
        <child link="waist" />
        <axis xyz="0 0 1" />
        <limit effort="0.5" lower="-1.57" upper="1.57" velocity="2" />
    </joint>
    <link name="lower_arm">
        <inertial>
            <origin rpy="0 0 0" xyz="3.93901868173032E-07 0.0592049065989172 0.00178916982484342" />
            <mass value="0.0651630231570887" />
            <inertia ixx="0.0001091601766917" ixy="1.57817877665133E-12" ixz="-1.63546197405558E-10" iyy="9.28177418562022E-06" iyz="2.43213344379075E-07" izz="0.000114063850988314" />
        </inertial>
        <visual>
            <origin rpy="0 0 0" xyz="0 0 0" />
            <geometry>
                <mesh filename="package://mocha/meshes/lower_arm.STL" />
            </geometry>
            <material name="">
                <color rgba="1 1 1 1" />
            </material>
        </visual>
        <collision>
            <origin rpy="0 0 0" xyz="0 0 0" />
            <geometry>
                <mesh filename="package://mocha/meshes/lower_arm.STL" />
            </geometry>
        </collision>
    </link>
    <joint name="lower_arm_joint" type="revolute">
        <origin rpy="1.5708 0 0" xyz="0.014 -0.002 0.036" />
        <parent link="waist" />
        <child link="lower_arm" />
        <axis xyz="0 0 -1" />
        <limit effort="0.5" lower="-1.57" upper="1.57" velocity="2" />
    </joint>
    <link name="upper_arm">
        <inertial>
            <origin rpy="0 0 0" xyz="2.73149762194391E-05 -0.0392975972882241 -0.0134097745057252" />
            <mass value="0.0516349186566131" />
            <inertia ixx="5.57007690316697E-05" ixy="7.13258826752884E-08" ixz="-1.33389234030937E-10" iyy="9.57834353936765E-06" iyz="-2.93374413537984E-07" izz="5.94244390323794E-05" />
        </inertial>
        <visual>
            <origin rpy="0 0 0" xyz="0 0 0" />
            <geometry>
                <mesh filename="package://mocha/meshes/upper_arm.STL" />
            </geometry>
            <material name="">
                <color rgba="1 1 1 1" />
            </material>
        </visual>
        <collision>
            <origin rpy="0 0 0" xyz="0 0 0" />
            <geometry>
                <mesh filename="package://mocha/meshes/upper_arm.STL" />
            </geometry>
        </collision>
    </link>
    <joint name="upper_arm_joint" type="revolute">
        <origin rpy="0 0 1.5708" xyz="0 0.12 0" />
        <parent link="lower_arm" />
        <child link="upper_arm" />
        <axis xyz="0 0 -1" />
        <limit effort="0.5" lower="-1.57" upper="1.57" velocity="2" />
    </joint>
    <link name="wrist">
        <inertial>
            <origin rpy="0 0 0" xyz="-0.000251495550924491 -0.0083404809422172 0.107614818148418" />
            <mass value="0.0171876871003583" />
            <inertia ixx="4.13711327481054E-06" ixy="4.3006748459359E-09" ixz="1.26235492993703E-08" iyy="5.26929296743607E-06" iyz="-6.19224470166822E-07" izz="2.72952486208993E-06" />
        </inertial>
        <visual>
            <origin rpy="0 0 0" xyz="0 0 0" />
            <geometry>
                <mesh filename="package://mocha/meshes/wrist.STL" />
            </geometry>
            <material name="">
                <color rgba="1 1 1 1" />
            </material>
        </visual>
        <collision>
            <origin rpy="0 0 0" xyz="0 0 0" />
            <geometry>
                <mesh filename="package://mocha/meshes/wrist.STL" />
            </geometry>
        </collision>
    </link>
    <joint name="wrist_joint" type="revolute">
        <origin rpy="1.5708 0 0" xyz="0 0 0" />
        <parent link="upper_arm" />
        <child link="wrist" />
        <axis xyz="0 0 -1" />
        <limit effort="0.5" lower="-1.57" upper="1.57" velocity="2" />
    </joint>
    <link name="gripper_base">
        <inertial>
            <origin rpy="0 0 0" xyz="-0.0235511395842871 -0.00581676654887205 -0.00697660952907593" />
            <mass value="0.016035839168366" />
            <inertia ixx="2.61166695995785E-06" ixy="-1.39141263089559E-06" ixz="-1.45711892942644E-06" iyy="8.27807706460361E-06" iyz="-3.57354311122567E-07" izz="7.39239283095659E-06" />
        </inertial>
        <visual>
            <origin rpy="0 0 0" xyz="0 0 0" />
            <geometry>
                <mesh filename="package://mocha/meshes/gripper_base.STL" />
            </geometry>
            <material name="">
                <color rgba="1 1 1 1" />
            </material>
        </visual>
        <collision>
            <origin rpy="0 0 0" xyz="0 0 0" />
            <geometry>
                <mesh filename="package://mocha/meshes/gripper_base.STL" />
            </geometry>
        </collision>
    </link>
    <joint name="gripper_base_joint" type="revolute">
        <origin rpy="-1.5708 0 0" xyz="-0.0003 0.0055 0.11815" />
        <parent link="wrist" />
        <child link="gripper_base" />
        <axis xyz="0 0 1" />
        <limit effort="0.5" lower="0" upper="3.14" velocity="2" />
    </joint>
    <link name="right_gear">
        <inertial>
            <origin rpy="0 0 0" xyz="0.000862162528650318 0.00554450246517772 0.002" />
            <mass value="0.00269444555032233" />
            <inertia ixx="3.71793221229667E-07" ixy="-3.66151898287318E-09" ixz="-3.11247770814466E-22" iyy="9.15764277476901E-08" iyz="-4.18219490705315E-22" izz="4.56184460843164E-07" />
        </inertial>
        <visual>
            <origin rpy="0 0 0" xyz="0 0 0" />
            <geometry>
                <mesh filename="package://mocha/meshes/right_gear.STL" />
            </geometry>
            <material name="">
                <color rgba="1 1 1 1" />
            </material>
        </visual>
        <collision>
            <origin rpy="0 0 0" xyz="0 0 0" />
            <geometry>
                <mesh filename="package://mocha/meshes/right_gear.STL" />
            </geometry>
        </collision>
    </link>
    <joint name="right_gear_joint" type="revolute">
        <origin rpy="1.5708 0 3.1416" xyz="-0.038 -0.0215 0.004" />
        <parent link="gripper_base" />
        <child link="right_gear" />
        <axis xyz="0 0 -1" />
        <limit effort="0.5" lower="0" upper="3.14" velocity="2" />
        <mimic joint="left_gear_joint" multiplier="1" offset="0" />
    </joint>
    <link name="right_finger">
        <inertial>
            <origin rpy="0 0 0" xyz="0.0267479392094104 -0.00529029293468648 0.00825002259150889" />
            <mass value="0.00550542078574704" />
            <inertia ixx="1.15006391171339E-07" ixy="1.91197506802569E-07" ixz="-1.71052844021085E-12" iyy="1.69947685318375E-06" iyz="1.42084945996662E-11" izz="1.74818882959069E-06" />
        </inertial>
        <visual>
            <origin rpy="0 0 0" xyz="0 0 0" />
            <geometry>
                <mesh filename="package://mocha/meshes/right_finger.STL" />
            </geometry>
            <material name="">
                <color rgba="1 1 1 1" />
            </material>
        </visual>
        <collision>
            <origin rpy="0 0 0" xyz="0 0 0" />
            <geometry>
                <mesh filename="package://mocha/meshes/right_finger.STL" />
            </geometry>
        </collision>
    </link>
    <joint name="right_finger_joint" type="revolute">
        <origin rpy="0 0 0" xyz="0.0014378 0.030716 0" />
        <parent link="right_gear" />
        <child link="right_finger" />
        <axis xyz="0 0 -1" />
        <limit effort="0.5" lower="0" upper="3.14" velocity="2" />
        <mimic joint="left_gear_joint" multiplier="-1" offset="0" />
    </joint>
    <link name="left_gear">
        <inertial>
            <origin rpy="0 0 0" xyz="0.000868914166758522 -0.00563101926893944 -0.002" />
            <mass value="0.00261717686273073" />
            <inertia ixx="3.70848537895313E-07" ixy="3.28405598542026E-09" ixz="-3.23827368834952E-22" iyy="9.12164029816256E-08" iyz="-4.58013781424372E-22" izz="4.55085802576324E-07" />
        </inertial>
        <visual>
            <origin rpy="0 0 0" xyz="0 0 0" />
            <geometry>
                <mesh filename="package://mocha/meshes/left_gear.STL" />
            </geometry>
            <material name="">
                <color rgba="1 1 1 1" />
            </material>
        </visual>
        <collision>
            <origin rpy="0 0 0" xyz="0 0 0" />
            <geometry>
                <mesh filename="package://mocha/meshes/left_gear.STL" />
            </geometry>
        </collision>
    </link>
    <joint name="left_gear_joint" type="revolute">
        <origin rpy="1.5708 0 3.1416" xyz="-0.038 -0.0175 -0.0229" />
        <parent link="gripper_base" />
        <child link="left_gear" />
        <axis xyz="0 0 1" />
        <limit effort="0.5" lower="0" upper="3.14" velocity="2" />
    </joint>
    <link name="left_finger">
        <inertial>
            <origin rpy="0 0 0" xyz="0.0264952988065887 0.00643728187189994 0.00824997740849176" />
            <mass value="0.00550542088206421" />
            <inertia ixx="1.34397312995325E-07" ixy="-2.58659921284749E-07" ixz="1.09467430768046E-12" iyy="1.68008574838117E-06" iyz="1.42676907042123E-11" izz="1.74818864591621E-06" />
        </inertial>
        <visual>
            <origin rpy="0 0 0" xyz="0 0 0" />
            <geometry>
                <mesh filename="package://mocha/meshes/left_finger.STL" />
            </geometry>
            <material name="">
                <color rgba="1 1 1 1" />
            </material>
        </visual>
        <collision>
            <origin rpy="0 0 0" xyz="0 0 0" />
            <geometry>
                <mesh filename="package://mocha/meshes/left_finger.STL" />
            </geometry>
        </collision>
    </link>
    <joint name="left_finger_joint" type="revolute">
        <origin rpy="0 0 0" xyz="0.0014378 -0.030716 -0.004" />
        <parent link="left_gear" />
        <child link="left_finger" />
        <axis xyz="0 0 -1" />
        <limit effort="0.5" lower="0" upper="3.14" velocity="2" />
        <mimic joint="left_gear_joint" multiplier="1" offset="0" />
    </joint>
    <link name="right_link">
        <inertial>
            <origin rpy="0 0 0" xyz="0.00100774826959747 0.0154672054174738 0.00200000000000006" />
            <mass value="0.000814737661448385" />
            <inertia ixx="1.04552091697251E-07" ixy="-6.57056810897569E-09" ixz="-1.39427938070675E-23" iyy="4.1332522394072E-09" iyz="-1.17131498885849E-22" izz="1.06512710172796E-07" />
        </inertial>
        <visual>
            <origin rpy="0 0 0" xyz="0 0 0" />
            <geometry>
                <mesh filename="package://mocha/meshes/right_link.STL" />
            </geometry>
            <material name="">
                <color rgba="1 1 1 1" />
            </material>
        </visual>
        <collision>
            <origin rpy="0 0 0" xyz="0 0 0" />
            <geometry>
                <mesh filename="package://mocha/meshes/right_link.STL" />
            </geometry>
        </collision>
    </link>
    <joint name="right_link_joint" type="revolute">
        <origin rpy="1.5708 0 3.1416" xyz="-0.058 -0.0215 -0.004" />
        <parent link="gripper_base" />
        <child link="right_link" />
        <axis xyz="0 0 -1" />
        <limit effort="0.5" lower="0" upper="3.14" velocity="2" />
        <mimic joint="left_gear_joint" multiplier="1" offset="0" />
    </joint>
    <link name="left_link">
        <inertial>
            <origin rpy="0 0 0" xyz="0.000830638506810533 -0.0154777272126691 0.002" />
            <mass value="0.000814737661448385" />
            <inertia ixx="1.04689343606938E-07" ixy="5.41948795586974E-09" ixz="1.26001100056874E-24" iyy="3.99600032972003E-09" iyz="-1.15348736080485E-22" izz="1.06512710172796E-07" />
        </inertial>
        <visual>
            <origin rpy="0 0 0" xyz="0 0 0" />
            <geometry>
                <mesh filename="package://mocha/meshes/left_link.STL" />
            </geometry>
            <material name="">
                <color rgba="1 1 1 1" />
            </material>
        </visual>
        <collision>
            <origin rpy="0 0 0" xyz="0 0 0" />
            <geometry>
                <mesh filename="package://mocha/meshes/left_link.STL" />
            </geometry>
        </collision>
    </link>
    <joint name="left_link_joint" type="revolute">
        <origin rpy="1.5708 0 3.1416" xyz="-0.058 -0.0215 -0.014" />
        <parent link="gripper_base" />
        <child link="left_link" />
        <axis xyz="0 0 -1" />
        <limit effort="0.5" lower="0" upper="3.14" velocity="2" />
        <mimic joint="left_gear_joint" multiplier="-1" offset="0" />
    </joint>
    <gazebo>
        <plugin filename="libgazebo_ros_control.so" name="gazebo_ros_control">
            <robotSimType>gazebo_ros_control/DefaultRobotHWSim</robotSimType>
            <legacyModeNS>true</legacyModeNS>
            <robotNamespace>/mocha</robotNamespace>
        </plugin>
        <plugin filename="libroboticsgroup_gazebo_mimic_joint_plugin.so" name="right_gear_joint_mimic_left_gear_joint">
            <joint>left_gear_joint</joint>
            <mimicJoint>right_gear_joint</mimicJoint>
            <multiplier>-1.0</multiplier>
            <offset>0</offset>
            <maxEffort>0.5</maxEffort>
            <robotNamespace>/mocha</robotNamespace>
        </plugin>
    </gazebo>
    <transmission name="transmission_waist_joint">
        <type>transmission_interface/SimpleTransmission</type>
        <joint name="waist_joint">
            <hardwareInterface>hardware_interface/PositionJointInterface</hardwareInterface>
        </joint>
        <actuator name="motor_waist_joint">
            <hardwareInterface>hardware_interface/PositionJointInterface</hardwareInterface>
            <mechanicalReduction>1</mechanicalReduction>
        </actuator>
    </transmission>
    <transmission name="transmission_lower_arm_joint">
        <type>transmission_interface/SimpleTransmission</type>
        <joint name="lower_arm_joint">
            <hardwareInterface>hardware_interface/PositionJointInterface</hardwareInterface>
        </joint>
        <actuator name="motor_lower_arm_joint">
            <hardwareInterface>hardware_interface/PositionJointInterface</hardwareInterface>
            <mechanicalReduction>1</mechanicalReduction>
        </actuator>
    </transmission>
    <transmission name="transmission_upper_arm_joint">
        <type>transmission_interface/SimpleTransmission</type>
        <joint name="upper_arm_joint">
            <hardwareInterface>hardware_interface/PositionJointInterface</hardwareInterface>
        </joint>
        <actuator name="motor_upper_arm_joint">
            <hardwareInterface>hardware_interface/PositionJointInterface</hardwareInterface>
            <mechanicalReduction>1</mechanicalReduction>
        </actuator>
    </transmission>
    <transmission name="transmission_wrist_joint">
        <type>transmission_interface/SimpleTransmission</type>
        <joint name="wrist_joint">
            <hardwareInterface>hardware_interface/PositionJointInterface</hardwareInterface>
        </joint>
        <actuator name="motor_wrist_joint">
            <hardwareInterface>hardware_interface/PositionJointInterface</hardwareInterface>
            <mechanicalReduction>1</mechanicalReduction>
        </actuator>
    </transmission>
    <transmission name="transmission_gripper_base_joint">
        <type>transmission_interface/SimpleTransmission</type>
        <joint name="gripper_base_joint">
            <hardwareInterface>hardware_interface/PositionJointInterface</hardwareInterface>
        </joint>
        <actuator name="motor_gripper_base_joint">
            <hardwareInterface>hardware_interface/PositionJointInterface</hardwareInterface>
            <mechanicalReduction>1</mechanicalReduction>
        </actuator>
    </transmission>
    <transmission name="transmission_left_gear_joint">
        <type>transmission_interface/SimpleTransmission</type>
        <joint name="left_gear_joint">
            <hardwareInterface>hardware_interface/PositionJointInterface</hardwareInterface>
        </joint>
        <actuator name="motor_left_gear_joint">
            <hardwareInterface>hardware_interface/PositionJointInterface</hardwareInterface>
            <mechanicalReduction>1</mechanicalReduction>
        </actuator>
    </transmission>
    <transmission name="trans_right_gear_joint">
        <type>transmission_interface/SimpleTransmission</type>
        <joint name="right_gear_joint">
            <hardwareInterface>hardware_interface/EffortJointInterface</hardwareInterface>
        </joint>
        <actuator name="right_gear_joint_motor">
            <hardwareInterface>hardware_interface/EffortJointInterface</hardwareInterface>
            <mechanicalReduction>1</mechanicalReduction>
        </actuator>
    </transmission>
    <transmission name="trans_right_finger_joint">
        <type>transmission_interface/SimpleTransmission</type>
        <joint name="right_finger_joint">
            <hardwareInterface>hardware_interface/EffortJointInterface</hardwareInterface>
        </joint>
        <actuator name="right_finger_joint_motor">
            <hardwareInterface>hardware_interface/EffortJointInterface</hardwareInterface>
            <mechanicalReduction>1</mechanicalReduction>
        </actuator>
    </transmission>
    <transmission name="trans_left_finger_joint">
        <type>transmission_interface/SimpleTransmission</type>
        <joint name="left_finger_joint">
            <hardwareInterface>hardware_interface/EffortJointInterface</hardwareInterface>
        </joint>
        <actuator name="left_finger_joint_motor">
            <hardwareInterface>hardware_interface/EffortJointInterface</hardwareInterface>
            <mechanicalReduction>1</mechanicalReduction>
        </actuator>
    </transmission>
    <transmission name="trans_right_link_joint">
        <type>transmission_interface/SimpleTransmission</type>
        <joint name="right_link_joint">
            <hardwareInterface>hardware_interface/EffortJointInterface</hardwareInterface>
        </joint>
        <actuator name="right_link_joint_motor">
            <hardwareInterface>hardware_interface/EffortJointInterface</hardwareInterface>
            <mechanicalReduction>1</mechanicalReduction>
        </actuator>
    </transmission>
    <transmission name="trans_left_link_joint">
        <type>transmission_interface/SimpleTransmission</type>
        <joint name="left_link_joint">
            <hardwareInterface>hardware_interface/EffortJointInterface</hardwareInterface>
        </joint>
        <actuator name="left_link_joint_motor">
            <hardwareInterface>hardware_interface/EffortJointInterface</hardwareInterface>
            <mechanicalReduction>1</mechanicalReduction>
        </actuator>
    </transmission>
</robot>

